Workbook
Name FID_1: [1]AGR_Fuels!$A$2

Sheet Comm_FIProcess
B2: ~FI_Comm | K2: ~FI_Process
B3: Csets | C3: CommName | D3: CommDesc | E3: Unit | F3: LimType | G3: CTSLvl | H3: PeakTS | I3: Ctype | K3: Sets | L3: TechName | M3: TechDesc | N3: Tact | O3: Tcap | P3: Tslvl | Q3: PrimaryCG | R3: Vintage
B4: DEM | C4: R_ES-SD-SpHeat | E4: PJ | K4: DMD | L4: R_ES-SH-SD_OIL_NE | N4: PJ | O4: GW | R4: Yes
B5: DEM | C5: R_ES-SA-SpHeat | E5: PJ | L5: R_ES-SH-SD_OIL_ME | N5: PJ | O5: GW | R5: Yes
B6: DEM | C6: R_ES-AP-SpHeat | E6: PJ | L6: R_ES-SH-SD_OIL_HE | N6: PJ | O6: GW | R6: Yes
B7: DEM | C7: R_ES-MOB-SpHeat | E7: PJ | L7: R_ES-SH-SD_GAS_NE | N7: PJ | O7: GW | R7: Yes
B8: DEM | C8: R_ES-SD-SpCool | E8: PJ | L8: R_ES-SH-SD_GAS_ME | N8: PJ | O8: GW | R8: Yes
B9: DEM | C9: R_ES-SA-SpCool | E9: PJ | L9: R_ES-SH-SD_GAS_HE | N9: PJ | O9: GW | R9: Yes
B10: DEM | C10: R_ES-AP-SpCool | E10: PJ | L10: R_ES-SH-SD_ELC | N10: PJ | O10: GW | R10: Yes
B11: DEM | C11: R_ES-MOB-SpCool | E11: PJ | L11: R_ES-SH-SD_HET | N11: PJ | O11: GW | R11: Yes
B12: DEM | C12: R_ES-SD-WatHeat | E12: PJ | L12: R_ES-SH-SD_COAPRO | N12: PJ | O12: GW | R12: Yes
B13: DEM | C13: R_ES-SA-WatHeat | E13: PJ | L13: R_ES-SH-SD_WOD | N13: PJ | O13: GW | R13: Yes
B14: DEM | C14: R_ES-AP-WatHeat | E14: PJ | L14: R_ES-SH-SD_WOD_ELC | N14: PJ | O14: GW | R14: Yes
B15: DEM | C15: R_ES-MOB-WatHeat | E15: PJ | L15: R_ES-SH-SD_WOD_OIL | N15: PJ | O15: GW | R15: Yes
B16: DEM | C16: R_ES-APP-RE | E16: PJ | L16: R_ES-SH-SD_GAS_ELC | N16: PJ | O16: GW | R16: Yes
... B23: DEM | C23: R_ES-LI | E23: PJ | L23: R_ES-SH-SA_GAS_HE | N23: PJ | O23: GW | R23: Yes
B24: NRG | C24: RSDHET | E24: PJ | G24: SEASON | L24: R_ES-SH-SA_ELC | N24: PJ | O24: GW | R24: Yes
B25: NRG | C25: RSDCOAPRO | D25: Residential Fuel - Solids | E25: PJ | L25: R_ES-SH-SA_HET | N25: PJ | O25: GW | R25: Yes
B26: NRG | C26: RSDWOD | E26: PJ | L26: R_ES-SH-SA_COAPRO | N26: PJ | O26: GW | R26: Yes
B27: NRG | C27: RSDELC | D27: Residential Fuel - Electricity | E27: PJ | G27: DAYNITE | L27: R_ES-SH-SA_WOD | N27: PJ | O27: GW | R27: Yes
B28: NRG | C28: RSDGAS | D28: Residential Fuel - Gases | E28: PJ | G28: SEASON | L28: R_ES-SH-SA_WOD_ELC | N28: PJ | O28: GW | R28: Yes
B29: NRG | C29: RSDOIL | D29: Residential Fuel - GDO and other liquids (incl. liq. bio.) | E29: PJ | L29: R_ES-SH-SA_WOD_OIL | N29: PJ | O29: GW | R29: Yes
B30: NRG | C30: RSDSTEAM | E30: PJ | G30: DAYNITE | L30: R_ES-SH-SA_GAS_ELC | N30: PJ | O30: GW | R30: Yes
B31: ENV | C31: RSDCO2N | D31: Carbon Dioxide - RSDbustion (RSD) | E31: kt | L31: R_ES-SH-SA_OIL_ELC | N31: PJ | O31: GW | R31: Yes
B32: ENV | C32: RSDCOXN | D32: Carbon Monoxide - RSDbustion (RSD) | E32: kt | L32: R_ES-SH-AP_OIL_NE | N32: PJ | O32: GW | R32: Yes
B33: ENV | C33: RSDCH4N | D33: Methane - RSDbustion (RSD) | E33: kt | L33: R_ES-SH-AP_OIL_ME | N33: PJ | O33: GW | R33: Yes
B34: ENV | C34: RSDSO2N | D34: Sulphur Dioxide - RSDbustion (RSD) | E34: kt | L34: R_ES-SH-AP_OIL_HE | N34: PJ | O34: GW | R34: Yes
B35: ENV | C35: RSDNOXN | D35: Nitrogen Oxides - RSDbustion (RSD) | E35: kt | L35: R_ES-SH-AP_GAS_NE | N35: PJ | O35: GW | R35: Yes
B36: ENV | C36: RSDN2ON | D36: Nitrous Oxide - RSDbustion (RSD) | E36: kt | L36: R_ES-SH-AP_GAS_ME | N36: PJ | O36: GW | R36: Yes
B37: ENV | C37: RSDPMAN | D37: Particulate 2.5 - RSDbustion (RSD) | E37: kt | L37: R_ES-SH-AP_GAS_HE | N37: PJ | O37: GW | R37: Yes
B38: ENV | C38: RSDPMBN | D38: Particulate 10 - RSDbustion (RSD) | E38: kt | L38: R_ES-SH-AP_ELC | N38: PJ | O38: GW | R38: Yes
B39: ENV | C39: RSDVOCN | D39: Volatile Organic RSDpounds - RSDbustion (RSD) | E39: kt | L39: R_ES-SH-AP_HET | N39: PJ | O39: GW | R39: Yes
B40: ENV | C40: RSDSF6N | D40: Sulphur Hexafluoride - RSDbustion (RSD) | E40: kg | L40: R_ES-SH-AP_COAPRO | N40: PJ | O40: GW | R40: Yes
B41: ENV | C41: RSDCXFN | D41: Fluoro Carbons - RSDbustion (RSD) | E41: kg | L41: R_ES-SH-AP_WOD | N41: PJ | O41: GW | R41: Yes
L42: R_ES-SH-AP_WOD_ELC | N42: PJ | O42: GW | R42: Yes
L43: R_ES-SH-AP_WOD_OIL | N43: PJ | O43: GW | R43: Yes
L44: R_ES-SH-AP_GAS_ELC | N44: PJ | O44: GW | R44: Yes
L45: R_ES-SH-AP_OIL_ELC | N45: PJ | O45: GW | R45: Yes
L46: R_ES-SH-MOB_OIL_NE | N46: PJ | O46: GW | R46: Yes
L47: R_ES-SH-MOB_OIL_ME | N47: PJ | O47: GW | R47: Yes
...

Sheet Tech_Fuel
H6: ~FI_T: Share-I~UP | Y6: ~FI_T: Share-O~UP
F7: TechName | G7: Comm-IN | H7: Comm-OUT | I7: 2020 | J7: AT | K7: QU | L7: ON | M7: MA | N7: SA | O7: AL | P7: BC | W7: TechName | X7: Comm-IN | Y7: Comm-OUT | Z7: 2020 | AA7: AT | AB7: QU | AC7: ON | AD7: MA | AE7: SA | AF7: AL | AG7: BC
F8: RSDCOAPRO00 | G8: COAHAR | H8: RSDCOAPRO | J8: =(1-J9)/2 -> 0.22446406 | K8: =(1-K9)/2 -> 0.48407715 | L8: =(1-L9)/2 -> 0.5 | M8: =(1-M9)/2 -> 0.5 | N8: =(1-N9)/2 -> 0.5 | O8: =(1-O9)/2 -> 0.48672076 | P8: =(1-P9)/2 -> 0.48912295 | W8: RSDELCSTEAM00 | X8: ELC | Y8: RSDSTEAM | AA8: 0.5 | AB8: =(1-AB9)/2 -> 0.5 | AC8: =(1-AC9)/2 -> 0.5 | AD8: =(1-AD9)/2 -> 0.5 | AE8: =(1-AE9)/2 -> 0.5 | AF8: =(1-AF9)/2 -> 0.5 | AG8: =(1-AG9)/2 -> 0.5
G9: COACOK | J9: 0.55107188 | K9: 0.031845705 | L9: 0 | M9: 0 | N9: 0 | O9: 0.026558484 | P9: 0.02175411 | Y9: RSDELC | AV9: calibrated using Eurostat 2020 (2017 version)
G10: COALIG | J10: =J8 -> 0.22446406 | K10: =K8 -> 0.48407715 | L10: =L8 -> 0.5 | M10: =M8 -> 0.5 | N10: =N8 -> 0.5 | O10: =O8 -> 0.48672076 | P10: =P8 -> 0.48912295
F11: *
F12: RSDOIL00 | G12: OILGSL | H12: RSDOIL | J12: =25% -> 0.25 | K12: =25% -> 0.25 | L12: =25% -> 0.25 | M12: =25% -> 0.25 | N12: =25% -> 0.25 | O12: =25% -> 0.25 | P12: =25% -> 0.25
G13: OILKER | J13: =25% -> 0.25 | K13: =25% -> 0.25 | L13: =25% -> 0.25 | M13: =25% -> 0.25 | N13: =25% -> 0.25 | O13: =25% -> 0.25 | P13: =25% -> 0.25
G14: OILDST | J14: =25% -> 0.25 | K14: =25% -> 0.25 | L14: =25% -> 0.25 | M14: =25% -> 0.25 | N14: =25% -> 0.25 | O14: =25% -> 0.25 | P14: =25% -> 0.25
G15: OILHFO | J15: =25% -> 0.25 | K15: =25% -> 0.25 | L15: =25% -> 0.25 | M15: =25% -> 0.25 | N15: =25% -> 0.25 | O15: =25% -> 0.25 | P15: =25% -> 0.25
F16: *
F17: RSDGAS00 | G17: GASNAT | H17: RSDGAS | J17: 1 | K17: 1 | L17: 1 | M17: 1 | N17: 1 | O17: 1 | P17: 1
G18: GASP2G
H23: FI_T: Life
F24: TechName | G24: Comm-IN | H24: Comm-OUT | I24: 2020 | J24: AT | K24: QU | L24: ON | M24: MA | N24: SA | O24: AL | P24: BC
F25: RSDHET00 | J25: 40 | K25: 40 | L25: 40 | M25: 40 | N25: 40 | O25: 40 | P25: 40
F26: RSDCOAPRO00 | J26: 40 | K26: 40 | L26: 40 | M26: 40 | N26: 40 | O26: 40 | P26: 40
F27: RSDWOD00 | J27: 40 | K27: 40 | L27: 40 | M27: 40 | N27: 40 | O27: 40 | P27: 40
F28: RSDELCSTEAM00 | J28: 40 | K28: 40 | L28: 40 | M28: 40 | N28: 40 | O28: 40 | P28: 40
F29: RSDGAS00 | J29: 40 | K29: 40 | L29: 40 | M29: 40 | N29: 40 | O29: 40 | P29: 40
F30: RSDOIL00 | J30: 40 | K30: 40 | L30: 40 | M30: 40 | N30: 40 | O30: 40 | P30: 40
H34: ~FI_T: CAP2ACT
F35: TechName | G35: Comm-IN | H35: Comm-OUT | I35: AT | J35: QU | K35: ON | L35: MA | M35: SA | N35: AL | O35: BC
F36: RSDELCSTEAM00 | I36: 31.536 | J36: 31.536 | K36: 31.536 | L36: 31.536 | M36: 31.536 | N36: 31.536 | O36: 31.536
F37: RSDHET00 | I37: 31.536 | J37: 31.536 | K37: 31.536 | L37: 31.536 | M37: 31.536 | N37: 31.536 | O37: 31.536
F38: RSDCOAPRO00 | I38: 1 | J38: 1 | K38: 1 | L38: 1 | M38: 1 | N38: 1 | O38: 1
F39: RSDWOD00 | I39: 1 | J39: 1 | K39: 1 | L39: 1 | M39: 1 | N39: 1 | O39: 1
F40: RSDGAS00 | I40: 1 | J40: 1 | K40: 1 | L40: 1 | M40: 1 | N40: 1 | O40: 1
F41: RSDOIL00 | I41: 1 | J41: 1 | K41: 1 | L41: 1 | M41: 1 | N41: 1 | O41: 1
H46: ~FI_T: Peak
F47: TechName | G47: Comm-IN | H47: Comm-OUT | I47: AT | J47: QU | K47: ON | L47: MA | M47: SA | N47: AL | O47: BC
F48: RSDELCSTEAM00 | I48: 1 | J48: 1 | K48: 1 | L48: 1 | M48: 1 | N48: 1 | O48: 1
F49: RSDHET00 | I49: 1 | J49: 1 | K49: 1 | L49: 1 | M49: 1 | N49: 1 | O49: 1
H57: ~FI_T: AFA
F58: TechName | G58: Comm-IN | H58: Comm-OUT | I58: AT | J58: QU | K58: ON | L58: MA | M58: SA | N58: AL | O58: BC
F59: RSDHET00 | I59: 0.33 | J59: 0.33 | K59: 0.33 | L59: 0.33 | M59: 0.33 | N59: 0.33 | O59: 0.33
F60: RSDELCSTEAM00 | I60: 1 | J60: 1 | K60: 1 | L60: 1 | M60: 1 | N60: 1 | O60: 1
F61: RSDCOAPRO00 | I61: 1 | J61: 1 | K61: 1 | L61: 1 | M61: 1 | N61: 1 | O61: 1
F62: RSDWOD00 | I62: 1 | J62: 1 | K62: 1 | L62: 1 | M62: 1 | N62: 1 | O62: 1
F63: RSDGAS00 | I63: 1 | J63: 1 | K63: 1 | L63: 1 | M63: 1 | N63: 1 | O63: 1
...

Sheet EMI
B3: Dynamic coefficients for combustion emissions in RSDidential
B4: ~COMEMI
B5: CommName | C5: RSDCOA | D5: RSDOIL | E5: RSDGAS | F5: RSDCOAPRO
B6: RSDCO2N | C6: 97 | D6: 78 | E6: 56 | F6: 97
B7: RSDCOXN | C7: 0 | D7: 0 | E7: 0
B8: RSDCH4N | C8: 0 | D8: 0 | E8: 0
B9: RSDSO2N | C9: 0 | D9: 0 | E9: 0
B10: RSDNOXN | C10: 0 | D10: 0 | E10: 0
B11: RSDN2ON | C11: 0 | D11: 0 | E11: 0
B12: RSDPMAN | C12: 0 | D12: 0 | E12: 0
B13: RSDPMBN | C13: 0 | D13: 0 | E13: 0
B14: RSDVOCN | C14: 0 | D14: 0 | E14: 0
B15: RSDSF6N | C15: 0 | D15: 0 | E15: 0
B16: RSDCXFN | C16: 0 | D16: 0 | E16: 0

Sheet TechHeat-RES-SD
F1: ~FI_T: Stock
D2: TechName | E2: Comm-IN | F2: Comm-OUT | G2: AT | H2: QU | I2: ON | J2: MA | K2: SA | L2: AL | M2: BC | O2: CAP per dwelling (Mw) | R2: the unit for this tabel nr is GW because the stock unit is thousand
B3: Single Detached | C3: =attached_heating_EFF!B14 -> Heating Oil – Normal Efficiency | D3: R_ES-SH-SD_OIL_NE | E3: RSDOIL | F3: R_ES-SD-SpHeat | G3: =attached_DetachedHeatingStock!W15*'TechHeat-RES-SD'!O3 -> 0 | H3: =attached_DetachedHeatingStock!AU15*'TechHeat-RES-SD'!O3 -> 0 | I3: =attached_DetachedHeatingStock!BS15*'TechHeat-RES-SD'!O3 -> 0 | J3: =attached_DetachedHeatingStock!CQ15*'TechHeat-RES-SD'!O3 -> 0 | K3: =attached_DetachedHeatingStock!DO15*'TechHeat-RES-SD'!O3 -> 0 | L3: =attached_DetachedHeatingStock!EM15*'TechHeat-RES-SD'!O3 -> 0 | M3: =attached_DetachedHeatingStock!FK15*'TechHeat-RES-SD'!O3 -> 0.0011 | O3: 0.001
C4: =attached_heating_EFF!B15 -> Heating Oil – Medium Efficiency | D4: R_ES-SH-SD_OIL_ME | E4: RSDOIL | F4: R_ES-SD-SpHeat | G4: =attached_DetachedHeatingStock!W16*'TechHeat-RES-SD'!O4 -> 0.137 | H4: =attached_DetachedHeatingStock!AU16*'TechHeat-RES-SD'!O4 -> 0.073 | I4: =attached_DetachedHeatingStock!BS16*'TechHeat-RES-SD'!O4 -> 0.0662 | J4: =attached_DetachedHeatingStock!CQ16*'TechHeat-RES-SD'!O4 -> 0.0016 | K4: =attached_DetachedHeatingStock!DO16*'TechHeat-RES-SD'!O4 -> 0.0052 | L4: =attached_DetachedHeatingStock!EM16*'TechHeat-RES-SD'!O4 -> 0.0022 | M4: =attached_DetachedHeatingStock!FK16*'TechHeat-RES-SD'!O4 -> 0.0345 | O4: 0.001
C5: =attached_heating_EFF!B16 -> Heating Oil – High Efficiency | D5: R_ES-SH-SD_OIL_HE | E5: RSDOIL | F5: R_ES-SD-SpHeat | G5: =attached_DetachedHeatingStock!W17*'TechHeat-RES-SD'!O5 -> 0 | H5: =attached_DetachedHeatingStock!AU17*'TechHeat-RES-SD'!O5 -> 0 | I5: =attached_DetachedHeatingStock!BS17*'TechHeat-RES-SD'!O5 -> 0 | J5: =attached_DetachedHeatingStock!CQ17*'TechHeat-RES-SD'!O5 -> 0 | K5: =attached_DetachedHeatingStock!DO17*'TechHeat-RES-SD'!O5 -> 0 | L5: =attached_DetachedHeatingStock!EM17*'TechHeat-RES-SD'!O5 -> 0 | M5: =attached_DetachedHeatingStock!FK17*'TechHeat-RES-SD'!O5 -> 0 | O5: 0.001
C6: =attached_heating_EFF!B17 -> Natural Gas – Normal Efficiency | D6: R_ES-SH-SD_GAS_NE | E6: RSDGAS | F6: R_ES-SD-SpHeat | G6: =attached_DetachedHeatingStock!W18*'TechHeat-RES-SD'!O6 -> 0.0001 | H6: =attached_DetachedHeatingStock!AU18*'TechHeat-RES-SD'!O6 -> 0 | I6: =attached_DetachedHeatingStock!BS18*'TechHeat-RES-SD'!O6 -> 0 | J6: =attached_DetachedHeatingStock!CQ18*'TechHeat-RES-SD'!O6 -> 0 | K6: =attached_DetachedHeatingStock!DO18*'TechHeat-RES-SD'!O6 -> 0 | L6: =attached_DetachedHeatingStock!EM18*'TechHeat-RES-SD'!O6 -> 0 | M6: =attached_DetachedHeatingStock!FK18*'TechHeat-RES-SD'!O6 -> 0 | O6: 0.001
C7: =attached_heating_EFF!B18 -> Natural Gas – Medium Efficiency | D7: R_ES-SH-SD_GAS_ME | E7: RSDGAS | F7: R_ES-SD-SpHeat | G7: =attached_DetachedHeatingStock!W19*'TechHeat-RES-SD'!O7 -> 0.0021 | H7: =attached_DetachedHeatingStock!AU19*'TechHeat-RES-SD'!O7 -> 0.0069 | I7: =attached_DetachedHeatingStock!BS19*'TechHeat-RES-SD'!O7 -> 0.3825 | J7: =attached_DetachedHeatingStock!CQ19*'TechHeat-RES-SD'!O7 -> 0.0365 | K7: =attached_DetachedHeatingStock!DO19*'TechHeat-RES-SD'!O7 -> 0.0648 | L7: =attached_DetachedHeatingStock!EM19*'TechHeat-RES-SD'!O7 -> 0.365 | M7: =attached_DetachedHeatingStock!FK19*'TechHeat-RES-SD'!O7 -> 0.1626 | O7: 0.001
C8: =attached_heating_EFF!B19 -> Natural Gas – High Efficiency | D8: R_ES-SH-SD_GAS_HE | E8: RSDGAS | F8: R_ES-SD-SpHeat | G8: =attached_DetachedHeatingStock!W20*'TechHeat-RES-SD'!O8 -> 0.0175 | H8: =attached_DetachedHeatingStock!AU20*'TechHeat-RES-SD'!O8 -> 0.0741 | I8: =attached_DetachedHeatingStock!BS20*'TechHeat-RES-SD'!O8 -> 1.6006 | J8: =attached_DetachedHeatingStock!CQ20*'TechHeat-RES-SD'!O8 -> 0.1528 | K8: =attached_DetachedHeatingStock!DO20*'TechHeat-RES-SD'!O8 -> 0.2076 | L8: =attached_DetachedHeatingStock!EM20*'TechHeat-RES-SD'!O8 -> 0.5124 | M8: =attached_DetachedHeatingStock!FK20*'TechHeat-RES-SD'!O8 -> 0.2652 | O8: 0.001
C9: =attached_heating_EFF!B20 -> Electric | D9: R_ES-SH-SD_ELC | E9: RSDELC | F9: R_ES-SD-SpHeat | G9: =attached_DetachedHeatingStock!W21*'TechHeat-RES-SD'!O9 -> 0.4358 | H9: =attached_DetachedHeatingStock!AU21*'TechHeat-RES-SD'!O9 -> 0.7725 | I9: =attached_DetachedHeatingStock!BS21*'TechHeat-RES-SD'!O9 -> 0.4337 | J9: =attached_DetachedHeatingStock!CQ21*'TechHeat-RES-SD'!O9 -> 0.1293 | K9: =attached_DetachedHeatingStock!DO21*'TechHeat-RES-SD'!O9 -> 0.0402 | L9: =attached_DetachedHeatingStock!EM21*'TechHeat-RES-SD'!O9 -> 0.1218 | M9: =attached_DetachedHeatingStock!FK21*'TechHeat-RES-SD'!O9 -> 0.3731 | O9: 0.001
C10: =attached_heating_EFF!B21 -> Heat Pump | D10: R_ES-SH-SD_HET | E10: RSDHET | F10: R_ES-SD-SpHeat | G10: =attached_DetachedHeatingStock!W22*'TechHeat-RES-SD'!O10 -> 0.0329 | H10: =attached_DetachedHeatingStock!AU22*'TechHeat-RES-SD'!O10 -> 0.2157 | I10: =attached_DetachedHeatingStock!BS22*'TechHeat-RES-SD'!O10 -> 0.3293 | J10: =attached_DetachedHeatingStock!CQ22*'TechHeat-RES-SD'!O10 -> 0.0148 | K10: =attached_DetachedHeatingStock!DO22*'TechHeat-RES-SD'!O10 -> 0.0138 | L10: =attached_DetachedHeatingStock!EM22*'TechHeat-RES-SD'!O10 -> 0.0355 | M10: =attached_DetachedHeatingStock!FK22*'TechHeat-RES-SD'!O10 -> 0.0475 | O10: 0.001
C11: =attached_heating_EFF!B22 -> Other1 | D11: R_ES-SH-SD_COAPRO | E11: RSDCOAPRO | F11: R_ES-SD-SpHeat | G11: =attached_DetachedHeatingStock!W23*'TechHeat-RES-SD'!O11 -> 0.0094 | H11: =attached_DetachedHeatingStock!AU23*'TechHeat-RES-SD'!O11 -> 0.0065 | I11: =attached_DetachedHeatingStock!BS23*'TechHeat-RES-SD'!O11 -> 0.0938 | J11: =attached_DetachedHeatingStock!CQ23*'TechHeat-RES-SD'!O11 -> 0.0014 | K11: =attached_DetachedHeatingStock!DO23*'TechHeat-RES-SD'!O11 -> 0.004 | L11: =attached_DetachedHeatingStock!EM23*'TechHeat-RES-SD'!O11 -> 0.008 | M11: =attached_DetachedHeatingStock!FK23*'TechHeat-RES-SD'!O11 -> 0.0087 | O11: 0.001
C12: =attached_heating_EFF!B23 -> Wood | D12: R_ES-SH-SD_WOD | E12: RSDWOD | F12: R_ES-SD-SpHeat | G12: =attached_DetachedHeatingStock!W24*'TechHeat-RES-SD'!O12 -> 0 | H12: =attached_DetachedHeatingStock!AU24*'TechHeat-RES-SD'!O12 -> 0 | I12: =attached_DetachedHeatingStock!BS24*'TechHeat-RES-SD'!O12 -> 0 | J12: =attached_DetachedHeatingStock!CQ24*'TechHeat-RES-SD'!O12 -> 0 | K12: =attached_DetachedHeatingStock!DO24*'TechHeat-RES-SD'!O12 -> 0 | L12: =attached_DetachedHeatingStock!EM24*'TechHeat-RES-SD'!O12 -> 0 | M12: =attached_DetachedHeatingStock!FK24*'TechHeat-RES-SD'!O12 -> 0.0012 | O12: 0.001
C13: Wood/Electric | D13: R_ES-SH-SD_WOD_ELC | E13: RSDELC | F13: R_ES-SD-SpHeat | G13: =attached_DetachedHeatingStock!W26*'TechHeat-RES-SD'!O13 -> 0.0703 | H13: =attached_DetachedHeatingStock!AU26*'TechHeat-RES-SD'!O13 -> 0.3663 | I13: =attached_DetachedHeatingStock!BS26*'TechHeat-RES-SD'!O13 -> 0.1204 | J13: =attached_DetachedHeatingStock!CQ26*'TechHeat-RES-SD'!O13 -> 0.0171 | K13: =attached_DetachedHeatingStock!DO26*'TechHeat-RES-SD'!O13 -> 0.0023 | L13: =attached_DetachedHeatingStock!EM26*'TechHeat-RES-SD'!O13 -> 0.0015 | M13: =attached_DetachedHeatingStock!FK26*'TechHeat-RES-SD'!O13 -> 0.0819 | O13: 0.001
E14: RSDWOD | O14: 0.001
C15: Wood/Heating Oil | D15: R_ES-SH-SD_WOD_OIL | E15: RSDOIL | F15: R_ES-SD-SpHeat | G15: =attached_DetachedHeatingStock!W27*'TechHeat-RES-SD'!O15 -> 0.0654 | H15: =attached_DetachedHeatingStock!AU27*'TechHeat-RES-SD'!O15 -> 0.0938 | I15: =attached_DetachedHeatingStock!BS27*'TechHeat-RES-SD'!O15 -> 0.1082 | J15: =attached_DetachedHeatingStock!CQ27*'TechHeat-RES-SD'!O15 -> 0.0028 | K15: =attached_DetachedHeatingStock!DO27*'TechHeat-RES-SD'!O15 -> 0.0033 | L15: =attached_DetachedHeatingStock!EM27*'TechHeat-RES-SD'!O15 -> 0.0051 | M15: =attached_DetachedHeatingStock!FK27*'TechHeat-RES-SD'!O15 -> 0.0288 | O15: 0.001
E16: RSDWOD | O16: 0.001
C17: Natural Gas/Electric | D17: R_ES-SH-SD_GAS_ELC | E17: RSDELC | F17: R_ES-SD-SpHeat | G17: =attached_DetachedHeatingStock!W28*'TechHeat-RES-SD'!O17 -> 0 | H17: =attached_DetachedHeatingStock!AU28*'TechHeat-RES-SD'!O17 -> 0.0112 | I17: =attached_DetachedHeatingStock!BS28*'TechHeat-RES-SD'!O17 -> 0.0254 | J17: =attached_DetachedHeatingStock!CQ28*'TechHeat-RES-SD'!O17 -> 0.0005 | K17: =attached_DetachedHeatingStock!DO28*'TechHeat-RES-SD'!O17 -> 0.0022 | L17: =attached_DetachedHeatingStock!EM28*'TechHeat-RES-SD'!O17 -> 0.0041 | M17: =attached_DetachedHeatingStock!FK28*'TechHeat-RES-SD'!O17 -> 0.019 | O17: 0.001
E18: RSDGAS | O18: 0.001
C19: Heating Oil/Electric | D19: R_ES-SH-SD_OIL_ELC | E19: RSDELC | F19: R_ES-SD-SpHeat | G19: =attached_DetachedHeatingStock!W29*'TechHeat-RES-SD'!O19 -> 0.0057 | H19: =attached_DetachedHeatingStock!AU29*'TechHeat-RES-SD'!O19 -> 0.1131 | I19: =attached_DetachedHeatingStock!BS29*'TechHeat-RES-SD'!O19 -> 0.0157 | J19: =attached_DetachedHeatingStock!CQ29*'TechHeat-RES-SD'!O19 -> 0.0017 | K19: =attached_DetachedHeatingStock!DO29*'TechHeat-RES-SD'!O19 -> 0.0017 | L19: =attached_DetachedHeatingStock!EM29*'TechHeat-RES-SD'!O19 -> 0.0001 | M19: =attached_DetachedHeatingStock!FK29*'TechHeat-RES-SD'!O19 -> 0.01 | O19: 0.001
E20: RSDOIL | O20: 0.001
O21: 0.001
F25: ~FI_T: EFF
D26: TechName | E26: Comm-IN | F26: Comm-OUT | G26: AT | H26: QU | I26: ON | J26: MA | K26: SA | L26: AL | M26: BC
D27: R_ES-SH-SD_OIL_NE | E27: RSDOIL | F27: R_ES-SD-SpHeat | G27: =attached_heating_EFF!W14*0.01 -> 0.6 | H27: =attached_heating_EFF!AU14*0.01 -> 0.6 | I27: =attached_heating_EFF!BS14*0.01 -> 0.6 | J27: =attached_heating_EFF!CQ14/100 -> 0.6 | K27: =attached_heating_EFF!DO14*0.01 -> 0.6 | L27: =attached_heating_EFF!EM14/100 -> 0.6 | M27: =attached_heating_EFF!FK14/100 -> 0.6
D28: R_ES-SH-SD_OIL_ME | E28: RSDOIL | F28: R_ES-SD-SpHeat | G28: =attached_heating_EFF!W15*0.01 -> 0.78 | H28: =attached_heating_EFF!AU15*0.01 -> 0.78 | I28: =attached_heating_EFF!BS15*0.01 -> 0.78 | J28: =attached_heating_EFF!CQ15/100 -> 0.78 | K28: =attached_heating_EFF!DO15*0.01 -> 0.78 | L28: =attached_heating_EFF!EM15/100 -> 0.78 | M28: =attached_heating_EFF!FK15/100 -> 0.78
D29: R_ES-SH-SD_OIL_HE | E29: RSDOIL | F29: R_ES-SD-SpHeat | G29: =attached_heating_EFF!W16*0.01 -> 0.85 | H29: =attached_heating_EFF!AU16*0.01 -> 0.85 | I29: =attached_heating_EFF!BS16*0.01 -> 0.85 | J29: =attached_heating_EFF!CQ16/100 -> 0.85 | K29: =attached_heating_EFF!DO16*0.01 -> 0.85 | L29: =attached_heating_EFF!EM16/100 -> 0.85 | M29: =attached_heating_EFF!FK16/100 -> 0.85
D30: R_ES-SH-SD_GAS_NE | E30: RSDGAS | F30: R_ES-SD-SpHeat | G30: =attached_heating_EFF!W17*0.01 -> 0.62 | H30: =attached_heating_EFF!AU17*0.01 -> 0.62 | I30: =attached_heating_EFF!BS17*0.01 -> 0.62 | J30: =attached_heating_EFF!CQ17/100 -> 0.62 | K30: =attached_heating_EFF!DO17*0.01 -> 0.62 | L30: =attached_heating_EFF!EM17/100 -> 0.62 | M30: =attached_heating_EFF!FK17/100 -> 0.62
D31: R_ES-SH-SD_GAS_ME | E31: RSDGAS | F31: R_ES-SD-SpHeat | G31: =attached_heating_EFF!W18*0.01 -> 0.8 | H31: =attached_heating_EFF!AU18*0.01 -> 0.8 | I31: =attached_heating_EFF!BS18*0.01 -> 0.8 | J31: =attached_heating_EFF!CQ18/100 -> 0.8 | K31: =attached_heating_EFF!DO18*0.01 -> 0.8 | L31: =attached_heating_EFF!EM18/100 -> 0.8 | M31: =attached_heating_EFF!FK18/100 -> 0.8
D32: R_ES-SH-SD_GAS_HE | E32: RSDGAS | F32: R_ES-SD-SpHeat | G32: =attached_heating_EFF!W19*0.01 -> 0.9 | H32: =attached_heating_EFF!AU19*0.01 -> 0.9 | I32: =attached_heating_EFF!BS19*0.01 -> 0.9 | J32: =attached_heating_EFF!CQ19/100 -> 0.9 | K32: =attached_heating_EFF!DO19*0.01 -> 0.9 | L32: =attached_heating_EFF!EM19/100 -> 0.9 | M32: =attached_heating_EFF!FK19/100 -> 0.9
D33: R_ES-SH-SD_ELC | E33: RSDELC | F33: R_ES-SD-SpHeat | G33: =attached_heating_EFF!W20*0.01 -> 1 | H33: =attached_heating_EFF!AU20*0.01 -> 1 | I33: =attached_heating_EFF!BS20*0.01 -> 1 | J33: =attached_heating_EFF!CQ20/100 -> 1 | K33: =attached_heating_EFF!DO20*0.01 -> 1 | L33: =attached_heating_EFF!EM20/100 -> 1 | M33: =attached_heating_EFF!FK20/100 -> 1
D34: R_ES-SH-SD_HET | E34: RSDHET | F34: R_ES-SD-SpHeat | G34: =attached_heating_EFF!W21*0.01 -> 1.9 | H34: =attached_heating_EFF!AU21*0.01 -> 1.9 | I34: =attached_heating_EFF!BS21*0.01 -> 1.9 | J34: =attached_heating_EFF!CQ21/100 -> 1.9 | K34: =attached_heating_EFF!DO21*0.01 -> 1.9 | L34: =attached_heating_EFF!EM21/100 -> 1.9 | M34: =attached_heating_EFF!FK21/100 -> 1.9
D35: R_ES-SH-SD_COAPRO | E35: RSDCOAPRO | F35: R_ES-SD-SpHeat | G35: =attached_heating_EFF!W22*0.01 -> 0.5 | H35: =attached_heating_EFF!AU22*0.01 -> 0.5 | I35: =attached_heating_EFF!BS22*0.01 -> 0.5 | J35: =attached_heating_EFF!CQ22/100 -> 0.5 | K35: =attached_heating_EFF!DO22*0.01 -> 0.5 | L35: =attached_heating_EFF!EM22/100 -> 0.5 | M35: =attached_heating_EFF!FK22/100 -> 0.5
D36: R_ES-SH-SD_WOD | E36: RSDWOD | F36: R_ES-SD-SpHeat | G36: =attached_heating_EFF!W23*0.01 -> 0.5 | H36: =attached_heating_EFF!AU23*0.01 -> 0.5 | I36: =attached_heating_EFF!BS23*0.01 -> 0.5 | J36: =attached_heating_EFF!CQ23/100 -> 0.5 | K36: =attached_heating_EFF!DO23*0.01 -> 0.5 | L36: =attached_heating_EFF!EM23/100 -> 0.5 | M36: =attached_heating_EFF!FK23/100 -> 0.5
D37: R_ES-SH-SD_WOD_ELC | E37: RSDELC | F37: R_ES-SD-SpHeat | G37: 0.75 | H37: 0.75 | I37: 0.75 | J37: 0.75 | K37: 0.75 | L37: 0.75 | M37: 0.75 | O37: 0.75 | P37: 0.75 | Q37: 0.75 | R37: 0.75 | S37: 0.75 | T37: 0.75 | U37: 0.75
E38: RSDWOD
D39: R_ES-SH-SD_WOD_OIL | E39: RSDOIL | F39: R_ES-SD-SpHeat | G39: 0.675 | H39: 0.675 | I39: 0.675 | J39: 0.675 | K39: 0.675 | L39: 0.675 | M39: 0.675 | O39: 0.675 | P39: 0.675 | Q39: 0.675 | R39: 0.675 | S39: 0.675 | T39: 0.675 | U39: 0.675
E40: RSDWOD
D41: R_ES-SH-SD_GAS_ELC | E41: RSDELC | F41: R_ES-SD-SpHeat | G41: 0.9 | H41: 0.9 | I41: 0.9 | J41: 0.9 | K41: 0.9 | L41: 0.9 | M41: 0.9 | O41: 0.9 | P41: 0.9 | Q41: 0.9 | R41: 0.9 | S41: 0.9 | T41: 0.9 | U41: 0.9
E42: RSDGAS
D43: R_ES-SH-SD_OIL_ELC | E43: RSDELC | F43: R_ES-SD-SpHeat | G43: 0.89 | H43: 0.89 | I43: 0.89 | J43: 0.89 | K43: 0.89 | L43: 0.89 | M43: 0.89 | O43: 0.89 | P43: 0.89 | Q43: 0.89 | R43: 0.89 | S43: 0.89 | T43: 0.89 | U43: 0.89
...

Sheet attached_DetachedHeatingStock
A5: Residential Sector | Y5: Residential Sector | AW5: Residential Sector | BU5: Residential Sector | CS5: Residential Sector | DQ5: Residential Sector | EO5: Residential Sector
A7: Atlantic | Y7: Quebec | AW7: Ontario | BU7: Manitoba | CS7: Saskatchewan | DQ7: Alberta | EO7: British Columbia and Territories1
A8: Table 22: Single Detached Heating System Stock by Heating System Type | Y8: Table 22: Single Detached Heating System Stock by Heating System Type | AW8: Table 22: Single Detached Heating System Stock by Heating System Type | BU8: Table 22: Single Detached Heating System Stock by Heating System Type | CS8: Table 22: Single Detached Heating System Stock by Heating System Type | DQ8: Table 22: Single Detached Heating System Stock by Heating System Type | EO8: Table 22: Single Detached Heating System Stock by Heating System Type
C11: 2000 | D11: 2001 | E11: 2002 | F11: 2003 | G11: 2004 | H11: 2005 | I11: 2006 | J11: 2007 | K11: 2008 | L11: 2009 | M11: 2010 | N11: 2011 | O11: 2012 | P11: 2013 | Q11: 2014 | R11: 2015 | S11: 2016 | T11: 2017 | U11: 2018 | V11: 2019 | W11: 2020 | AA11: 2000 | AB11: 2001 | AC11: 2002 | AD11: 2003 | AE11: 2004 | AF11: 2005 | AG11: 2006 | AH11: 2007 | AI11: 2008 | AJ11: 2009 | AK11: 2010 | AL11: 2011 | AM11: 2012 | AN11: 2013 | AO11: 2014 | AP11: 2015 | AQ11: 2016 | AR11: 2017 | AS11: 2018 | AT11: 2019 | AU11: 2020 | AY11: 2000 | AZ11: 2001 | BA11: 2002 | BB11: 2003 | BC11: 2004 | BD11: 2005 | BE11: 2006 | BF11: 2007 | BG11: 2008 | BH11: 2009 | BI11: 2010 | BJ11: 2011 | BK11: 2012 | BL11: 2013 | BM11: 2014 | BN11: 2015 | BO11: 2016 | BP11: 2017 | BQ11: 2018 | BR11: 2019 | BS11: 2020 | BW11: 2000 | BX11: 2001 | BY11: 2002 | BZ11: 2003 | CA11: 2004 | CB11: 2005 | CC11: 2006 | CD11: 2007 | CE11: 2008 | CF11: 2009 | CG11: 2010 | CH11: 2011 | CI11: 2012 | CJ11: 2013 | CK11: 2014 | CL11: 2015 | CM11: 2016 | CN11: 2017 | CO11: 2018 | CP11: 2019 | CQ11: 2020 | CU11: 2000 | CV11: 2001 | CW11: 2002 | CX11: 2003 | CY11: 2004 | CZ11: 2005 | DA11: 2006 | DB11: 2007 | DC11: 2008 | DD11: 2009 | DE11: 2010 | DF11: 2011 | DG11: 2012 | DH11: 2013 | DI11: 2014 | DJ11: 2015 | DK11: 2016 | DL11: 2017 | DM11: 2018 | DN11: 2019 | DO11: 2020 | DS11: 2000 | DT11: 2001 | DU11: 2002 | DV11: 2003 | DW11: 2004 | DX11: 2005 | DY11: 2006 | DZ11: 2007 | EA11: 2008 | EB11: 2009 | EC11: 2010 | ED11: 2011 | EE11: 2012 | EF11: 2013 | EG11: 2014 | EH11: 2015 | EI11: 2016 | EJ11: 2017 | EK11: 2018 | EL11: 2019 | EM11: 2020 | EQ11: 2000 | ER11: 2001 | ES11: 2002 | ET11: 2003 | EU11: 2004 | EV11: 2005 | EW11: 2006 | EX11: 2007 | EY11: 2008 | EZ11: 2009 | FA11: 2010 | FB11: 2011 | FC11: 2012 | FD11: 2013 | FE11: 2014 | FF11: 2015 | FG11: 2016 | FH11: 2017 | FI11: 2018 | FJ11: 2019 | FK11: 2020
B13: Total Single Detached Heating System Stock (thousands) | C13: 662.1 | D13: 668.1 | E13: 675 | F13: 684.1 | G13: 692.5 | H13: 700.2 | I13: 707.2 | J13: 714 | K13: 721.4 | L13: 728 | M13: 734.7 | N13: 741 | O13: 746.5 | P13: 751.7 | Q13: 755.8 | R13: 759.2 | S13: 762.5 | T13: 765.5 | U13: 769 | V13: 772.6 | W13: 776.1 | Z13: Total Single Detached Heating System Stock (thousands) | AA13: 1442.3 | AB13: 1457 | AC13: 1479.3 | AD13: 1503.2 | AE13: 1530 | AF13: 1551.2 | AG13: 1571.4 | AH13: 1591.6 | AI13: 1609.2 | AJ13: 1624.2 | AK13: 1641.1 | AL13: 1654.9 | AM13: 1669 | AN13: 1680.5 | AO13: 1690 | AP13: 1697.8 | AQ13: 1705.3 | AR13: 1712.9 | AS13: 1720 | AT13: 1726.4 | AU13: 1733.1 | AX13: Total Single Detached Heating System Stock (thousands) | AY13: 2526.9 | AZ13: 2566.5 | BA13: 2611.3 | BB13: 2655.4 | BC13: 2701 | BD13: 2741.5 | BE13: 2778.5 | BF13: 2812.1 | BG13: 2843.7 | BH13: 2865.7 | BI13: 2890.4 | BJ13: 2912.3 | BK13: 2935.7 | BL13: 2955.9 | BM13: 2975.8 | BN13: 2993.1 | BO13: 3021.3 | BP13: 3046.7 | BQ13: 3090.8 | BR13: 3139.1 | BS13: 3175.9 | BV13: Total Single Detached Heating System Stock (thousands) | BW13: 302 | BX13: 304.3 | BY13: 306.8 | BZ13: 309.5 | CA13: 312.6 | CB13: 316 | CC13: 319.2 | CD13: 322.4 | CE13: 325.7 | CF13: 328.6 | CG13: 332.1 | CH13: 335.3 | CI13: 338.2 | CJ13: 341.7 | CK13: 344.4 | CL13: 346.9 | CM13: 348.9 | CN13: 351.4 | CO13: 354 | CP13: 356.3 | CQ13: 358.5 | CT13: Total Single Detached Heating System Stock (thousands) | CU13: 294.5 | CV13: 295.9 | CW13: 297.4 | CX13: 299.2 | CY13: 300.9 | CZ13: 302.8 | DA13: 304.6 | DB13: 307.7 | DC13: 311.7 | DD13: 314.6 | DE13: 318 | DF13: 321.6 | DG13: 325.3 | DH13: 329.1 | DI13: 333.2 | DJ13: 336.2 | DK13: 338.3 | DL13: 341.1 | DM13: 342.8 | DN13: 343.9 | DO13: 345 | DR13: Total Single Detached Heating System Stock (thousands) | DS13: 733.4 | DT13: 749.8 | DU13: 769.7 | DV13: 790.7 | DW13: 810.5 | DX13: 832.9 | DY13: 856.2 | DZ13: 882.3 | EA13: 902.3 | EB13: 914.8 | EC13: 931 | ED13: 944.2 | EE13: 957.6 | EF13: 973.3 | EG13: 989.1 | EH13: 1005.1 | EI13: 1015.9 | EJ13: 1026.4 | EK13: 1037.6 | EL13: 1046.8 | EM13: 1055.8 | EP13: Total Single Detached Heating System Stock (thousands) | EQ13: 884.8 | ER13: 890.7 | ES13: 897.4 | ET13: 905.5 | EU13: 914.7 | EV13: 924.3 | EW13: 935.8 | EX13: 946.6 | EY13: 955 | EZ13: 961.5 | FA13: 969 | FB13: 976.2 | FC13: 981.8 | FD13: 988.4 | FE13: 994 | FF13: 999.2 | FG13: 1005 | FH13: 1011.9 | FI13: 1019.5 | FJ13: 1027 | FK13: 1033.6
B14: Heating System Stock by Heating System Type (thousands) | Z14: Heating System Stock by Heating System Type (thousands) | AX14: Heating System Stock by Heating System Type (thousands) | BV14: Heating System Stock by Heating System Type (thousands) | CT14: Heating System Stock by Heating System Type (thousands) | DR14: Heating System Stock by Heating System Type (thousands) | EP14: Heating System Stock by Heating System Type (thousands)
B15: Heating Oil – Normal Efficiency | C15: 99.5 | D15: 87.1 | E15: 73.9 | F15: 62 | G15: 51.6 | H15: 41.1 | I15: 32.1 | J15: 23.5 | K15: 15.5 | L15: 6.2 | M15: 0.9 | N15: 0 | O15: 0 | P15: 0 | Q15: 0 | R15: 0 | S15: 0 | T15: 0 | U15: 0 | V15: 0 | W15: 0 | Z15: Heating Oil – Normal Efficiency | AA15: 0 | AB15: 0 | AC15: 0 | AD15: 0 | AE15: 0 | AF15: 0 | AG15: 0 | AH15: 0 | AI15: 0 | AJ15: 0 | AK15: 0 | AL15: 0 | AM15: 0 | AN15: 0 | AO15: 0 | AP15: 0 | AQ15: 0 | AR15: 0 | AS15: 0 | AT15: 0 | AU15: 0 | AX15: Heating Oil – Normal Efficiency | AY15: 59.1 | AZ15: 41.9 | BA15: 22.1 | BB15: 7.8 | BC15: 0 | BD15: 0 | BE15: 0 | BF15: 0 | BG15: 0 | BH15: 0 | BI15: 0 | BJ15: 0 | BK15: 0 | BL15: 0 | BM15: 0 | BN15: 0 | BO15: 0 | BP15: 0 | BQ15: 0 | BR15: 0 | BS15: 0 | BV15: Heating Oil – Normal Efficiency | BW15: 1.4 | BX15: 0.8 | BY15: 0.4 | BZ15: 0.2 | CA15: 0 | CB15: 0 | CC15: 0 | CD15: 0 | CE15: 0 | CF15: 0 | CG15: 0 | CH15: 0 | CI15: 0 | CJ15: 0 | CK15: 0 | CL15: 0 | CM15: 0 | CN15: 0 | CO15: 0 | CP15: 0 | CQ15: 0 | CT15: Heating Oil – Normal Efficiency | CU15: 4.1 | CV15: 2.5 | CW15: 0.8 | CX15: 0 | CY15: 0 | CZ15: 0 | DA15: 0 | DB15: 0 | DC15: 0 | DD15: 0 | DE15: 0 | DF15: 0 | DG15: 0 | DH15: 0 | DI15: 0 | DJ15: 0 | DK15: 0 | DL15: 0 | DM15: 0 | DN15: 0 | DO15: 0 | DR15: Heating Oil – Normal Efficiency | DS15: 3.6 | DT15: 3.1 | DU15: 2.6 | DV15: 2.2 | DW15: 1.7 | DX15: 1.3 | DY15: 0.9 | DZ15: 0.5 | EA15: 0 | EB15: 0 | EC15: 0 | ED15: 0 | EE15: 0 | EF15: 0 | EG15: 0 | EH15: 0 | EI15: 0 | EJ15: 0 | EK15: 0 | EL15: 0 | EM15: 0 | EP15: Heating Oil – Normal Efficiency | EQ15: 21.6 | ER15: 16.2 | ES15: 10.9 | ET15: 5.4 | EU15: 4.9 | EV15: 4.4 | EW15: 4.1 | EX15: 3.6 | EY15: 3.5 | EZ15: 3.1 | FA15: 2.8 | FB15: 2.1 | FC15: 2.3 | FD15: 1.7 | FE15: 1.7 | FF15: 1.6 | FG15: 1.4 | FH15: 1 | FI15: 1.1 | FJ15: 0.6 | FK15: 1.1
B16: Heating Oil – Medium Efficiency | C16: 136.5 | D16: 149.9 | E16: 164.4 | F16: 175.5 | G16: 183.9 | H16: 191.3 | I16: 196.1 | J16: 199.5 | K16: 200.7 | L16: 201.1 | M16: 199.3 | N16: 195.5 | O16: 190.8 | P16: 185.5 | Q16: 179.5 | R16: 172.1 | S16: 163.4 | T16: 153.9 | U16: 147.9 | V16: 143 | W16: 137 | Z16: Heating Oil – Medium Efficiency | AA16: 136.9 | AB16: 139 | AC16: 145.6 | AD16: 144.8 | AE16: 144.3 | AF16: 142.8 | AG16: 141 | AH16: 139.2 | AI16: 137.9 | AJ16: 136.6 | AK16: 135.1 | AL16: 133.1 | AM16: 130.9 | AN16: 128.1 | AO16: 124.3 | AP16: 119.3 | AQ16: 112.7 | AR16: 104.6 | AS16: 95.1 | AT16: 84.4 | AU16: 73 | AX16: Heating Oil – Medium Efficiency | AY16: 113.6 | AZ16: 122.4 | BA16: 123.9 | BB16: 126.8 | BC16: 131.9 | BD16: 134.2 | BE16: 133.4 | BF16: 132.6 | BG16: 131.8 | BH16: 130.8 | BI16: 129.2 | BJ16: 127 | BK16: 124.2 | BL16: 120.3 | BM16: 114.1 | BN16: 107.2 | BO16: 99.9 | BP16: 92 | BQ16: 83.8 | BR16: 75.2 | BS16: 66.2 | BV16: Heating Oil – Medium Efficiency | BW16: 4.3 | BX16: 4.3 | BY16: 4.3 | BZ16: 4.3 | CA16: 4.3 | CB16: 4.3 | CC16: 4.3 | CD16: 4.3 | CE16: 4.3 | CF16: 4.3 | CG16: 4.3 | CH16: 4.3 | CI16: 4.2 | CJ16: 4.2 | CK16: 4 | CL16: 3.8 | CM16: 3.5 | CN16: 3.1 | CO16: 2.6 | CP16: 2.1 | CQ16: 1.6 | CT16: Heating Oil – Medium Efficiency | CU16: 6 | CV16: 7.4 | CW16: 7.5 | CX16: 7.6 | CY16: 7.6 | CZ16: 7.6 | DA16: 7.5 | DB16: 7.5 | DC16: 7.5 | DD16: 7.5 | DE16: 7.4 | DF16: 7.4 | DG16: 7.4 | DH16: 7.4 | DI16: 7.4 | DJ16: 7.3 | DK16: 7.1 | DL16: 6.8 | DM16: 6.4 | DN16: 5.9 | DO16: 5.2 | DR16: Heating Oil – Medium Efficiency | DS16: 1.3 | DT16: 1.7 | DU16: 2.1 | DV16: 2.6 | DW16: 2.9 | DX16: 3.1 | DY16: 3.2 | DZ16: 3.3 | EA16: 3.3 | EB16: 3.2 | EC16: 3.2 | ED16: 3.1 | EE16: 3 | EF16: 2.9 | EG16: 2.8 | EH16: 2.7 | EI16: 2.5 | EJ16: 2.4 | EK16: 2.3 | EL16: 2.2 | EM16: 2.2 | EP16: Heating Oil – Medium Efficiency | EQ16: 19.7 | ER16: 24.4 | ES16: 27.3 | ET16: 29.2 | EU16: 31.9 | EV16: 34.2 | EW16: 36.6 | EX16: 37.5 | EY16: 37.5 | EZ16: 37.7 | FA16: 37.9 | FB16: 39.5 | FC16: 39.5 | FD16: 40.1 | FE16: 39.6 | FF16: 39 | FG16: 38.4 | FH16: 37.7 | FI16: 36.6 | FJ16: 36 | FK16: 34.5
B17: Heating Oil – High Efficiency | C17: 0 | D17: 0 | E17: 0 | F17: 0 | G17: 0 | H17: 0 | I17: 0 | J17: 0 | K17: 0 | L17: 0 | M17: 0 | N17: 0 | O17: 0 | P17: 0 | Q17: 0 | R17: 0 | S17: 0 | T17: 0 | U17: 0 | V17: 0 | W17: 0 | Z17: Heating Oil – High Efficiency | AA17: 0 | AB17: 0 | AC17: 0 | AD17: 0 | AE17: 0 | AF17: 0 | AG17: 0 | AH17: 0 | AI17: 0 | AJ17: 0 | AK17: 0 | AL17: 0 | AM17: 0 | AN17: 0 | AO17: 0 | AP17: 0 | AQ17: 0 | AR17: 0 | AS17: 0 | AT17: 0 | AU17: 0 | AX17: Heating Oil – High Efficiency | AY17: 0 | AZ17: 0 | BA17: 0 | BB17: 0 | BC17: 0 | BD17: 0 | BE17: 0 | BF17: 0 | BG17: 0 | BH17: 0 | BI17: 0 | BJ17: 0 | BK17: 0 | BL17: 0 | BM17: 0 | BN17: 0 | BO17: 0 | BP17: 0 | BQ17: 0 | BR17: 0 | BS17: 0 | BV17: Heating Oil – High Efficiency | BW17: 0 | BX17: 0 | BY17: 0 | BZ17: 0 | CA17: 0 | CB17: 0 | CC17: 0 | CD17: 0 | CE17: 0 | CF17: 0 | CG17: 0 | CH17: 0 | CI17: 0 | CJ17: 0 | CK17: 0 | CL17: 0 | CM17: 0 | CN17: 0 | CO17: 0 | CP17: 0 | CQ17: 0 | CT17: Heating Oil – High Efficiency | CU17: 0 | CV17: 0 | CW17: 0 | CX17: 0 | CY17: 0 | CZ17: 0 | DA17: 0 | DB17: 0 | DC17: 0 | DD17: 0 | DE17: 0 | DF17: 0 | DG17: 0 | DH17: 0 | DI17: 0 | DJ17: 0 | DK17: 0 | DL17: 0 | DM17: 0 | DN17: 0 | DO17: 0 | DR17: Heating Oil – High Efficiency | DS17: 0 | DT17: 0 | DU17: 0 | DV17: 0 | DW17: 0 | DX17: 0 | DY17: 0 | DZ17: 0 | EA17: 0 | EB17: 0 | EC17: 0 | ED17: 0 | EE17: 0 | EF17: 0 | EG17: 0 | EH17: 0 | EI17: 0 | EJ17: 0 | EK17: 0 | EL17: 0 | EM17: 0 | EP17: Heating Oil – High Efficiency | EQ17: 0 | ER17: 0 | ES17: 0 | ET17: 0 | EU17: 0 | EV17: 0 | EW17: 0 | EX17: 0 | EY17: 0 | EZ17: 0 | FA17: 0 | FB17: 0 | FC17: 0 | FD17: 0 | FE17: 0 | FF17: 0 | FG17: 0 | FH17: 0 | FI17: 0 | FJ17: 0 | FK17: 0
B18: Natural Gas – Normal Efficiency | C18: 1.5 | D18: 1.5 | E18: 1.5 | F18: 1.5 | G18: 1.4 | H18: 1.3 | I18: 1.2 | J18: 1.1 | K18: 1 | L18: 0.9 | M18: 0.7 | N18: 0.6 | O18: 0.5 | P18: 0.4 | Q18: 0.3 | R18: 0.2 | S18: 0.1 | T18: 0.1 | U18: 0.2 | V18: 0.1 | W18: 0.1 | Z18: Natural Gas – Normal Efficiency | AA18: 51.7 | AB18: 50.2 | AC18: 45.7 | AD18: 41 | AE18: 35.2 | AF18: 29 | AG18: 22.4 | AH18: 15.9 | AI18: 9.9 | AJ18: 4.3 | AK18: 0 | AL18: 0 | AM18: 0 | AN18: 0 | AO18: 0 | AP18: 0 | AQ18: 0 | AR18: 0 | AS18: 0 | AT18: 0 | AU18: 0 | AX18: Natural Gas – Normal Efficiency | AY18: 735.9 | AZ18: 690 | BA18: 640 | BB18: 585.6 | BC18: 524.4 | BD18: 459.7 | BE18: 393.3 | BF18: 327.5 | BG18: 264.4 | BH18: 202.4 | BI18: 146 | BJ18: 92.6 | BK18: 43.2 | BL18: 0 | BM18: 0 | BN18: 0 | BO18: 0 | BP18: 0 | BQ18: 0 | BR18: 0 | BS18: 0 | BV18: Natural Gas – Normal Efficiency | BW18: 83.8 | BX18: 77.6 | BY18: 71.1 | BZ18: 64.6 | CA18: 57.8 | CB18: 51.1 | CC18: 44.4 | CD18: 37.8 | CE18: 31.5 | CF18: 25.8 | CG18: 20.4 | CH18: 15 | CI18: 9.9 | CJ18: 5.4 | CK18: 1.2 | CL18: 0 | CM18: 0 | CN18: 0 | CO18: 0 | CP18: 0 | CQ18: 0 | CT18: Natural Gas – Normal Efficiency | CU18: 139.1 | CV18: 129.6 | CW18: 120 | CX18: 109.7 | CY18: 98.5 | CZ18: 87.1 | DA18: 76.2 | DB18: 65.3 | DC18: 55 | DD18: 45.5 | DE18: 36.5 | DF18: 28 | DG18: 20.2 | DH18: 13.1 | DI18: 7.2 | DJ18: 1.9 | DK18: 0 | DL18: 0 | DM18: 0 | DN18: 0 | DO18: 0 | DR18: Natural Gas – Normal Efficiency | DS18: 328.2 | DT18: 304.5 | DU18: 278.9 | DV18: 254.8 | DW18: 221.8 | DX18: 191.9 | DY18: 163 | DZ18: 136 | EA18: 112.1 | EB18: 88.8 | EC18: 70.4 | ED18: 51.7 | EE18: 33.9 | EF18: 18.1 | EG18: 4.5 | EH18: 0 | EI18: 0 | EJ18: 0 | EK18: 0 | EL18: 0 | EM18: 0 | EP18: Natural Gas – Normal Efficiency | EQ18: 213.4 | ER18: 196.5 | ES18: 178.5 | ET18: 160.2 | EU18: 139.4 | EV18: 119.3 | EW18: 99.1 | EX18: 81.1 | EY18: 64.4 | EZ18: 46.7 | FA18: 33.4 | FB18: 21 | FC18: 9 | FD18: 0.3 | FE18: 0.2 | FF18: 0.2 | FG18: 0.1 | FH18: 0.1 | FI18: 0 | FJ18: 0 | FK18: 0
B19: Natural Gas – Medium Efficiency | C19: 3.5 | D19: 3.5 | E19: 3.6 | F19: 3.7 | G19: 3.7 | H19: 3.7 | I19: 3.7 | J19: 3.7 | K19: 3.7 | L19: 3.7 | M19: 3.6 | N19: 3.6 | O19: 3.5 | P19: 3.4 | Q19: 3.3 | R19: 3.3 | S19: 3.1 | T19: 3 | U19: 2.8 | V19: 2.5 | W19: 2.1 | Z19: Natural Gas – Medium Efficiency | AA19: 8 | AB19: 8.2 | AC19: 8.5 | AD19: 9.3 | AE19: 10.6 | AF19: 11.4 | AG19: 12.1 | AH19: 12.4 | AI19: 12.5 | AJ19: 12.4 | AK19: 12 | AL19: 11.4 | AM19: 10.8 | AN19: 10.3 | AO19: 9.7 | AP19: 9.1 | AQ19: 8.6 | AR19: 8 | AS19: 7.6 | AT19: 7.2 | AU19: 6.9 | AX19: Natural Gas – Medium Efficiency | AY19: 484.2 | AZ19: 518.7 | BA19: 556.2 | BB19: 588.9 | BC19: 617.6 | BD19: 640.2 | BE19: 658.6 | BF19: 674.9 | BG19: 681.9 | BH19: 683.5 | BI19: 675.6 | BJ19: 665.9 | BK19: 653.5 | BL19: 636.4 | BM19: 606.8 | BN19: 573.4 | BO19: 537.3 | BP19: 498.4 | BQ19: 459.3 | BR19: 420.5 | BS19: 382.5 | BV19: Natural Gas – Medium Efficiency | BW19: 49.3 | BX19: 52.8 | BY19: 55.7 | BZ19: 58.4 | CA19: 60.6 | CB19: 62.4 | CC19: 64.1 | CD19: 66.1 | CE19: 66.6 | CF19: 66.9 | CG19: 66.2 | CH19: 65.4 | CI19: 64.1 | CJ19: 62.4 | CK19: 60.2 | CL19: 57 | CM19: 53.2 | CN19: 49 | CO19: 44.8 | CP19: 40.6 | CQ19: 36.5 | CT19: Natural Gas – Medium Efficiency | CU19: 63.9 | CV19: 69.5 | CW19: 75.6 | CX19: 81.3 | CY19: 86.6 | CZ19: 91.7 | DA19: 96.2 | DB19: 99.2 | DC19: 101.4 | DD19: 101.8 | DE19: 100.9 | DF19: 99.7 | DG19: 98.3 | DH19: 96.3 | DI19: 93.7 | DJ19: 90.5 | DK19: 86 | DL19: 80.8 | DM19: 75.6 | DN19: 70.1 | DO19: 64.8 | DR19: Natural Gas – Medium Efficiency | DS19: 320.5 | DT19: 348.5 | DU19: 380.1 | DV19: 408.5 | DW19: 440.6 | DX19: 470.7 | DY19: 498.9 | DZ19: 523.6 | EA19: 535.4 | EB19: 542.2 | EC19: 538 | ED19: 532.4 | EE19: 525.3 | EF19: 516.2 | EG19: 504.6 | EH19: 486.8 | EI19: 464.8 | EJ19: 441.2 | EK19: 416.8 | EL19: 391 | EM19: 365 | EP19: Natural Gas – Medium Efficiency | EQ19: 162 | ER19: 173 | ES19: 187.2 | ET19: 202.2 | EU19: 215.3 | EV19: 227 | EW19: 237.9 | EX19: 247.2 | EY19: 252.3 | EZ19: 256.6 | FA19: 255.2 | FB19: 253.1 | FC19: 250 | FD19: 245.2 | FE19: 236.7 | FF19: 226.5 | FG19: 215.4 | FH19: 202.8 | FI19: 189.8 | FJ19: 176.2 | FK19: 162.6
B20: Natural Gas – High Efficiency | C20: 4 | D20: 4.1 | E20: 4.3 | F20: 4.6 | G20: 4.8 | H20: 5.2 | I20: 6.1 | J20: 7.3 | K20: 7.8 | L20: 8.1 | M20: 8.3 | N20: 8.9 | O20: 9.1 | P20: 9.3 | Q20: 9.4 | R20: 10.5 | S20: 12.7 | T20: 14.3 | U20: 15.2 | V20: 16.3 | W20: 17.5 | Z20: Natural Gas – High Efficiency | AA20: 10.7 | AB20: 11 | AC20: 11.7 | AD20: 13.9 | AE20: 18.4 | AF20: 22.3 | AG20: 27.1 | AH20: 34.5 | AI20: 39.5 | AJ20: 44.7 | AK20: 50.4 | AL20: 55.1 | AM20: 59.1 | AN20: 62.3 | AO20: 65.1 | AP20: 66.7 | AQ20: 69.1 | AR20: 70.5 | AS20: 72 | AT20: 73.1 | AU20: 74.1 | AX20: Natural Gas – High Efficiency | AY20: 392.8 | AZ20: 440.5 | BA20: 500.2 | BB20: 560.5 | BC20: 625.8 | BD20: 689.7 | BE20: 759.6 | BF20: 825 | BG20: 892.3 | BH20: 954.3 | BI20: 1022.6 | BJ20: 1087.5 | BK20: 1151.8 | BL20: 1213.3 | BM20: 1257.6 | BN20: 1302.1 | BO20: 1353.7 | BP20: 1404.4 | BQ20: 1471.8 | BR20: 1540.6 | BS20: 1600.6 | BV20: Natural Gas – High Efficiency | BW20: 40.5 | BX20: 45.6 | BY20: 50.5 | BZ20: 56 | CA20: 61.4 | CB20: 66.8 | CC20: 73.6 | CD20: 78.5 | CE20: 84.1 | CF20: 90.4 | CG20: 97.2 | CH20: 103.9 | CI20: 110.3 | CJ20: 116.7 | CK20: 122.9 | CL20: 128 | CM20: 132.6 | CN20: 137.4 | CO20: 142.9 | CP20: 148 | CQ20: 152.8 | CT20: Natural Gas – High Efficiency | CU20: 49.1 | CV20: 54.5 | CW20: 60.9 | CX20: 67.7 | CY20: 74.9 | CZ20: 82.7 | DA20: 90.3 | DB20: 100.4 | DC20: 111.3 | DD20: 122 | DE20: 133.6 | DF20: 144.9 | DG20: 155.5 | DH20: 165.7 | DI20: 175 | DJ20: 183 | DK20: 188.2 | DL20: 192.5 | DM20: 197.9 | DN20: 202.9 | DO20: 207.6 | DR20: Natural Gas – High Efficiency | DS20: 37.5 | DT20: 46.8 | DU20: 58.8 | DV20: 71 | DW20: 86.7 | DX20: 103.5 | DY20: 121.5 | DZ20: 143.2 | EA20: 169 | EB20: 189.9 | EC20: 222.1 | ED20: 252.8 | EE20: 283.5 | EF20: 315.5 | EG20: 347.4 | EH20: 376.6 | EI20: 400.7 | EJ20: 424.9 | EK20: 454.7 | EL20: 483.7 | EM20: 512.4 | EP20: Natural Gas – High Efficiency | EQ20: 90.7 | ER20: 97.6 | ES20: 107.1 | ET20: 117.8 | EU20: 127.9 | EV20: 137.7 | EW20: 147.1 | EX20: 155.5 | EY20: 166.5 | EZ20: 174.3 | FA20: 182.4 | FB20: 189.2 | FC20: 195.8 | FD20: 202.3 | FE20: 207.8 | FF20: 214.5 | FG20: 220.7 | FH20: 228.4 | FI20: 240.8 | FJ20: 253.4 | FK20: 265.2
B21: Electric | C21: 238.5 | D21: 242.5 | E21: 245.7 | F21: 252.1 | G21: 259.7 | H21: 268.2 | I21: 278.1 | J21: 288.2 | K21: 301 | L21: 316.8 | M21: 332.3 | N21: 345.7 | O21: 358.6 | P21: 371.7 | Q21: 383.6 | R21: 393.8 | S21: 403.9 | T21: 414.8 | U21: 422.2 | V21: 428.8 | W21: 435.8 | Z21: Electric | AA21: 616.5 | AB21: 622.4 | AC21: 634.4 | AD21: 651.4 | AE21: 667.7 | AF21: 683.1 | AG21: 703.3 | AH21: 719.9 | AI21: 732 | AJ21: 740.7 | AK21: 749.7 | AL21: 754.2 | AM21: 759.1 | AN21: 762.2 | AO21: 764.3 | AP21: 765.8 | AQ21: 767.3 | AR21: 769.7 | AS21: 770.4 | AT21: 771.3 | AU21: 772.5 | AX21: Electric | AY21: 338.1 | AZ21: 336.6 | BA21: 338 | BB21: 339.8 | BC21: 341.3 | BD21: 343.7 | BE21: 347.4 | BF21: 352 | BG21: 358.9 | BH21: 365.8 | BI21: 374 | BJ21: 381.9 | BK21: 389.9 | BL21: 397.4 | BM21: 399.8 | BN21: 402.8 | BO21: 408.5 | BP21: 414.6 | BQ21: 420.7 | BR21: 428.1 | BS21: 433.7 | BV21: Electric | BW21: 89.7 | BX21: 89.9 | BY21: 91.4 | BZ21: 91.6 | CA21: 94.1 | CB21: 96.9 | CC21: 98.4 | CD21: 101.5 | CE21: 104.9 | CF21: 107.2 | CG21: 110.1 | CH21: 112.9 | CI21: 115.4 | CJ21: 118.2 | CK21: 120.7 | CL21: 122.3 | CM21: 123.6 | CN21: 125.4 | CO21: 126.7 | CP21: 127.9 | CQ21: 129.3 | CT21: Electric | CU21: 8 | CV21: 7.6 | CW21: 7.3 | CX21: 7 | CY21: 6.9 | CZ21: 7 | DA21: 7.4 | DB21: 8.1 | DC21: 9.2 | DD21: 10.6 | DE21: 12.5 | DF21: 14.6 | DG21: 17.1 | DH21: 19.9 | DI21: 23 | DJ21: 26.5 | DK21: 30.2 | DL21: 34.2 | DM21: 36.1 | DN21: 38 | DO21: 40.2 | DR21: Electric | DS21: 11.4 | DT21: 13.1 | DU21: 13.8 | DV21: 17.1 | DW21: 20.9 | DX21: 25.1 | DY21: 30.1 | DZ21: 35.7 | EA21: 41 | EB21: 48 | EC21: 53.5 | ED21: 59.4 | EE21: 65.9 | EF21: 73.2 | EG21: 81.2 | EH21: 89.5 | EI21: 97.8 | EJ21: 106.8 | EK21: 111.6 | EL21: 116.5 | EM21: 121.8 | EP21: Electric | EQ21: 235.7 | ER21: 236.4 | ES21: 235.5 | ET21: 235.7 | EU21: 237.2 | EV21: 240.8 | EW21: 247 | EX21: 254.7 | EY21: 261.6 | EZ21: 271.3 | FA21: 282.9 | FB21: 294.2 | FC21: 305.5 | FD21: 316.8 | FE21: 325 | FF21: 333.4 | FG21: 343.3 | FH21: 354.1 | FI21: 360.4 | FJ21: 366.9 | FK21: 373.1
B22: Heat Pump | C22: 17 | D22: 17.9 | E22: 18.9 | F22: 19.9 | G22: 20.9 | H22: 21.9 | I22: 22.8 | J22: 23.7 | K22: 24.6 | L22: 25.5 | M22: 26.3 | N22: 26.9 | O22: 27.5 | P22: 28.1 | Q22: 28.7 | R22: 29.2 | S22: 29.8 | T22: 30.4 | U22: 31.2 | V22: 32 | W22: 32.9 | Z22: Heat Pump | AA22: 120.5 | AB22: 125.2 | AC22: 130.2 | AD22: 135.5 | AE22: 141 | AF22: 146.1 | AG22: 150.8 | AH22: 155.4 | AI22: 160.3 | AJ22: 165 | AK22: 169.5 | AL22: 173.4 | AM22: 177.5 | AN22: 181.6 | AO22: 185.6 | AP22: 189.8 | AQ22: 194.1 | AR22: 198.9 | AS22: 204.3 | AT22: 209.9 | AU22: 215.7 | AX22: Heat Pump | AY22: 160.6 | AZ22: 169.6 | BA22: 179.6 | BB22: 189.7 | BC22: 199.3 | BD22: 208.7 | BE22: 217 | BF22: 225.8 | BG22: 234.4 | BH22: 242.6 | BI22: 250.2 | BJ22: 257.7 | BK22: 265.9 | BL22: 273.5 | BM22: 278.1 | BN22: 282.8 | BO22: 289.8 | BP22: 296.9 | BQ22: 307.6 | BR22: 319 | BS22: 329.3 | BV22: Heat Pump | BW22: 7 | BX22: 7.3 | BY22: 7.7 | BZ22: 8.1 | CA22: 8.5 | CB22: 8.9 | CC22: 9.3 | CD22: 9.7 | CE22: 10.1 | CF22: 10.5 | CG22: 10.9 | CH22: 11.3 | CI22: 11.7 | CJ22: 12.1 | CK22: 12.6 | CL22: 12.9 | CM22: 13.2 | CN22: 13.6 | CO22: 14 | CP22: 14.3 | CQ22: 14.8 | CT22: Heat Pump | CU22: 6.7 | CV22: 7 | CW22: 7.3 | CX22: 7.6 | CY22: 8 | CZ22: 8.3 | DA22: 8.6 | DB22: 8.9 | DC22: 9.4 | DD22: 9.7 | DE22: 10.1 | DF22: 10.5 | DG22: 10.9 | DH22: 11.3 | DI22: 11.8 | DJ22: 12.2 | DK22: 12.5 | DL22: 12.8 | DM22: 13.2 | DN22: 13.5 | DO22: 13.8 | DR22: Heat Pump | DS22: 13.5 | DT22: 14.5 | DU22: 15.5 | DV22: 16.5 | DW22: 17.6 | DX22: 18.8 | DY22: 20 | DZ22: 21.4 | EA22: 22.6 | EB22: 23.7 | EC22: 24.8 | ED22: 25.9 | EE22: 27 | EF22: 28.3 | EG22: 29.6 | EH22: 30.6 | EI22: 31.5 | EJ22: 32.5 | EK22: 33.5 | EL22: 34.5 | EM22: 35.5 | EP22: Heat Pump | EQ22: 24.7 | ER22: 26 | ES22: 27.3 | ET22: 28.5 | EU22: 29.7 | EV22: 30.8 | EW22: 32.2 | EX22: 33.5 | EY22: 34.6 | EZ22: 35.7 | FA22: 36.9 | FB22: 38.1 | FC22: 39.2 | FD22: 40.3 | FE22: 41 | FF22: 41.8 | FG22: 42.7 | FH22: 43.7 | FI22: 45 | FJ22: 46.2 | FK22: 47.5
B23: Other1 | C23: 7.1 | D23: 7.1 | E23: 7.1 | F23: 7.8 | G23: 8.6 | H23: 9.3 | I23: 10 | J23: 10.7 | K23: 11.3 | L23: 12 | M23: 11.8 | N23: 11.5 | O23: 11.3 | P23: 11 | Q23: 10.7 | R23: 10.3 | S23: 10 | T23: 9.7 | U23: 9.6 | V23: 9.5 | W23: 9.4 | Z23: Other1 | AA23: 1.9 | AB23: 1.9 | AC23: 1.9 | AD23: 1.9 | AE23: 1.9 | AF23: 1.9 | AG23: 2 | AH23: 2.1 | AI23: 2.3 | AJ23: 2.5 | AK23: 2.8 | AL23: 3.1 | AM23: 3.4 | AN23: 3.7 | AO23: 4.1 | AP23: 4.6 | AQ23: 5 | AR23: 5.6 | AS23: 5.9 | AT23: 6.1 | AU23: 6.5 | AX23: Other1 | AY23: 31.8 | AZ23: 31.7 | BA23: 31.8 | BB23: 31.9 | BC23: 32.4 | BD23: 33.2 | BE23: 34.5 | BF23: 36.4 | BG23: 38.9 | BH23: 41.9 | BI23: 45.7 | BJ23: 49.8 | BK23: 54.3 | BL23: 59.1 | BM23: 63.6 | BN23: 68.6 | BO23: 74.5 | BP23: 80.9 | BQ23: 84.9 | BR23: 89.4 | BS23: 93.8 | BV23: Other1 | BW23: 2.9 | BX23: 2.9 | BY23: 2.9 | BZ23: 2.9 | CA23: 2.9 | CB23: 2.8 | CC23: 2.8 | CD23: 2.7 | CE23: 2.6 | CF23: 2.5 | CG23: 2.3 | CH23: 2.2 | CI23: 2.1 | CJ23: 2 | CK23: 1.9 | CL23: 1.7 | CM23: 1.6 | CN23: 1.5 | CO23: 1.5 | CP23: 1.4 | CQ23: 1.4 | CT23: Other1 | CU23: 5 | CV23: 5 | CW23: 5.1 | CX23: 5.1 | CY23: 5.1 | CZ23: 5.1 | DA23: 5.1 | DB23: 5 | DC23: 5 | DD23: 4.9 | DE23: 4.8 | DF23: 4.8 | DG23: 4.7 | DH23: 4.6 | DI23: 4.5 | DJ23: 4.4 | DK23: 4.3 | DL23: 4.2 | DM23: 4.1 | DN23: 4 | DO23: 4 | DR23: Other1 | DS23: 10.6 | DT23: 10.6 | DU23: 10.7 | DV23: 10.7 | DW23: 10.8 | DX23: 10.8 | DY23: 10.8 | DZ23: 10.8 | EA23: 10.7 | EB23: 10.5 | EC23: 10.2 | ED23: 10 | EE23: 9.7 | EF23: 9.5 | EG23: 9.3 | EH23: 9 | EI23: 8.7 | EJ23: 8.4 | EK23: 8.2 | EL23: 8.1 | EM23: 8 | EP23: Other1 | EQ23: 16.3 | ER23: 16.7 | ES23: 17.1 | ET23: 17.1 | EU23: 16.9 | EV23: 16.5 | EW23: 16.1 | EX23: 15.6 | EY23: 15 | EZ23: 14.3 | FA23: 13.5 | FB23: 13 | FC23: 12.3 | FD23: 11.7 | FE23: 11 | FF23: 10.3 | FG23: 9.8 | FH23: 9.2 | FI23: 9 | FJ23: 8.8 | FK23: 8.7
B24: Wood | C24: 19.1 | D24: 18 | E24: 17.9 | F24: 18.1 | G24: 17.8 | H24: 17.5 | I24: 15.9 | J24: 14.7 | K24: 13.4 | L24: 11 | M24: 8.7 | N24: 6.3 | O24: 3.8 | P24: 1.3 | Q24: 0 | R24: 0 | S24: 0 | T24: 0 | U24: 0 | V24: 0 | W24: 0 | Z24: Wood | AA24: 21.8 | AB24: 18.4 | AC24: 16.1 | AD24: 14.9 | AE24: 15.1 | AF24: 14.2 | AG24: 8.4 | AH24: 4.7 | AI24: 1.9 | AJ24: 0 | AK24: 0 | AL24: 0 | AM24: 0 | AN24: 0 | AO24: 0 | AP24: 0 | AQ24: 0 | AR24: 0 | AS24: 0 | AT24: 0 | AU24: 0 | AX24: Wood | AY24: 0 | AZ24: 0 | BA24: 0 | BB24: 0 | BC24: 0 | BD24: 0 | BE24: 0 | BF24: 0 | BG24: 0 | BH24: 0 | BI24: 0 | BJ24: 0 | BK24: 0 | BL24: 0 | BM24: 0 | BN24: 0 | BO24: 0 | BP24: 0 | BQ24: 0 | BR24: 0 | BS24: 0 | BV24: Wood | BW24: 5.7 | BX24: 5.4 | BY24: 4.8 | BZ24: 5 | CA24: 4.6 | CB24: 4 | CC24: 3.3 | CD24: 2.6 | CE24: 2 | CF24: 1.3 | CG24: 0.5 | CH24: 0 | CI24: 0 | CJ24: 0 | CK24: 0 | CL24: 0 | CM24: 0 | CN24: 0 | CO24: 0 | CP24: 0 | CQ24: 0 | CT24: Wood | CU24: 4.1 | CV24: 4.1 | CW24: 4.2 | CX24: 4.4 | CY24: 4.5 | CZ24: 4.5 | DA24: 4.4 | DB24: 4.2 | DC24: 3.9 | DD24: 3.6 | DE24: 3 | DF24: 2.5 | DG24: 2.1 | DH24: 1.6 | DI24: 1.3 | DJ24: 0.9 | DK24: 0.6 | DL24: 0.3 | DM24: 0.2 | DN24: 0.1 | DO24: 0 | DR24: Wood | DS24: 0.5 | DT24: 0.5 | DU24: 0.4 | DV24: 0.3 | DW24: 0.3 | DX24: 0.2 | DY24: 0.1 | DZ24: 0 | EA24: 0 | EB24: 0 | EC24: 0 | ED24: 0 | EE24: 0 | EF24: 0 | EG24: 0 | EH24: 0 | EI24: 0 | EJ24: 0 | EK24: 0 | EL24: 0 | EM24: 0 | EP24: Wood | EQ24: 0.9 | ER24: 0.9 | ES24: 0.9 | ET24: 1 | EU24: 1.1 | EV24: 1 | EW24: 1 | EX24: 1 | EY24: 1 | EZ24: 1 | FA24: 1 | FB24: 1.1 | FC24: 1.1 | FD24: 1.1 | FE24: 1.2 | FF24: 1.2 | FG24: 1.2 | FH24: 1.2 | FI24: 1.2 | FJ24: 1.2 | FK24: 1.2
B25: Dual Systems | Z25: Dual Systems | AX25: Dual Systems | BV25: Dual Systems | CT25: Dual Systems | DR25: Dual Systems | EP25: Dual Systems
B26: Wood/Electric | C26: 69.2 | D26: 69.7 | E26: 70.1 | F26: 70.5 | G26: 71 | H26: 71.1 | I26: 71.2 | J26: 71.2 | K26: 71.3 | L26: 71.4 | M26: 71.3 | N26: 70.8 | O26: 70.5 | P26: 70.3 | Q26: 70 | R26: 69.7 | S26: 69.4 | T26: 69.3 | U26: 69.6 | V26: 69.9 | W26: 70.3 | Z26: Wood/Electric | AA26: 313.1 | AB26: 316.2 | AC26: 318.1 | AD26: 320.5 | AE26: 322.8 | AF26: 324.9 | AG26: 326.4 | AH26: 327.7 | AI26: 330.2 | AJ26: 332.5 | AK26: 334.1 | AL26: 335.2 | AM26: 336.7 | AN26: 338.5 | AO26: 340.7 | AP26: 343.4 | AQ26: 346.5 | AR26: 350.3 | AS26: 355.3 | AT26: 360.7 | AU26: 366.3 | AX26: Wood/Electric | AY26: 97.2 | AZ26: 99 | BA26: 100.9 | BB26: 102.9 | BC26: 104.4 | BD26: 105.9 | BE26: 106.9 | BF26: 108.1 | BG26: 109.4 | BH26: 110.8 | BI26: 111.8 | BJ26: 112.9 | BK26: 114.1 | BL26: 115.2 | BM26: 115 | BN26: 115.1 | BO26: 115.5 | BP26: 116.3 | BQ26: 117.5 | BR26: 119 | BS26: 120.4 | BV26: Wood/Electric | BW26: 13.9 | BX26: 14.1 | BY26: 14.3 | BZ26: 14.5 | CA26: 14.7 | CB26: 14.9 | CC26: 15 | CD26: 15.2 | CE26: 15.4 | CF26: 15.6 | CG26: 15.7 | CH26: 15.9 | CI26: 16 | CJ26: 16.2 | CK26: 16.4 | CL26: 16.5 | CM26: 16.5 | CN26: 16.6 | CO26: 16.8 | CP26: 16.9 | CQ26: 17.1 | CT26: Wood/Electric | CU26: 2.5 | CV26: 2.5 | CW26: 2.5 | CX26: 2.5 | CY26: 2.4 | CZ26: 2.4 | DA26: 2.4 | DB26: 2.4 | DC26: 2.4 | DD26: 2.4 | DE26: 2.4 | DF26: 2.4 | DG26: 2.4 | DH26: 2.4 | DI26: 2.3 | DJ26: 2.3 | DK26: 2.3 | DL26: 2.3 | DM26: 2.3 | DN26: 2.3 | DO26: 2.3 | DR26: Wood/Electric | DS26: 0.9 | DT26: 1 | DU26: 1 | DV26: 1 | DW26: 1.1 | DX26: 1.1 | DY26: 1.1 | DZ26: 1.2 | EA26: 1.2 | EB26: 1.2 | EC26: 1.3 | ED26: 1.3 | EE26: 1.3 | EF26: 1.4 | EG26: 1.4 | EH26: 1.4 | EI26: 1.4 | EJ26: 1.5 | EK26: 1.5 | EL26: 1.5 | EM26: 1.5 | EP26: Wood/Electric | EQ26: 60.4 | ER26: 62.1 | ES26: 63.6 | ET26: 65.1 | EU26: 66.3 | EV26: 67.3 | EW26: 68.5 | EX26: 69.7 | EY26: 70.6 | EZ26: 71.7 | FA26: 72.9 | FB26: 74.1 | FC26: 75.2 | FD26: 76.2 | FE26: 76.6 | FF26: 77 | FG26: 77.8 | FH26: 78.6 | FI26: 79.7 | FJ26: 80.8 | FK26: 81.9
B27: Wood/Heating Oil | C27: 62.5 | D27: 63.1 | E27: 63.7 | F27: 64.3 | G27: 64.9 | H27: 65.3 | I27: 65.6 | J27: 66 | K27: 66.4 | L27: 66.7 | M27: 66.8 | N27: 66.4 | O27: 66 | P27: 65.7 | Q27: 65.3 | R27: 65 | S27: 64.7 | T27: 64.6 | U27: 64.9 | V27: 65 | W27: 65.4 | Z27: Wood/Heating Oil | AA27: 80.2 | AB27: 81 | AC27: 81.5 | AD27: 82.1 | AE27: 82.7 | AF27: 83.2 | AG27: 83.6 | AH27: 83.9 | AI27: 84.6 | AJ27: 85.2 | AK27: 85.6 | AL27: 85.9 | AM27: 86.2 | AN27: 86.7 | AO27: 87.3 | AP27: 88 | AQ27: 88.8 | AR27: 89.7 | AS27: 91 | AT27: 92.4 | AU27: 93.8 | AX27: Wood/Heating Oil | AY27: 87 | AZ27: 88.6 | BA27: 90.3 | BB27: 92.1 | BC27: 93.5 | BD27: 94.8 | BE27: 95.8 | BF27: 96.9 | BG27: 98.1 | BH27: 99.3 | BI27: 100.3 | BJ27: 101.3 | BK27: 102.4 | BL27: 103.4 | BM27: 103.3 | BN27: 103.3 | BO27: 103.8 | BP27: 104.5 | BQ27: 105.6 | BR27: 106.9 | BS27: 108.2 | BV27: Wood/Heating Oil | BW27: 2.2 | BX27: 2.3 | BY27: 2.3 | BZ27: 2.3 | CA27: 2.4 | CB27: 2.4 | CC27: 2.4 | CD27: 2.5 | CE27: 2.5 | CF27: 2.5 | CG27: 2.6 | CH27: 2.6 | CI27: 2.6 | CJ27: 2.7 | CK27: 2.7 | CL27: 2.7 | CM27: 2.7 | CN27: 2.8 | CO27: 2.8 | CP27: 2.8 | CQ27: 2.8 | CT27: Wood/Heating Oil | CU27: 3.6 | CV27: 3.6 | CW27: 3.6 | CX27: 3.6 | CY27: 3.6 | CZ27: 3.6 | DA27: 3.5 | DB27: 3.5 | DC27: 3.5 | DD27: 3.5 | DE27: 3.5 | DF27: 3.5 | DG27: 3.4 | DH27: 3.4 | DI27: 3.4 | DJ27: 3.4 | DK27: 3.4 | DL27: 3.3 | DM27: 3.3 | DN27: 3.3 | DO27: 3.3 | DR27: Wood/Heating Oil | DS27: 3.1 | DT27: 3.3 | DU27: 3.4 | DV27: 3.5 | DW27: 3.6 | DX27: 3.7 | DY27: 3.8 | DZ27: 3.9 | EA27: 4 | EB27: 4.1 | EC27: 4.2 | ED27: 4.3 | EE27: 4.4 | EF27: 4.5 | EG27: 4.6 | EH27: 4.7 | EI27: 4.8 | EJ27: 4.9 | EK27: 4.9 | EL27: 5 | EM27: 5.1 | EP27: Wood/Heating Oil | EQ27: 21.1 | ER27: 21.7 | ES27: 22.3 | ET27: 22.8 | EU27: 23.2 | EV27: 23.6 | EW27: 24 | EX27: 24.4 | EY27: 24.8 | EZ27: 25.2 | FA27: 25.6 | FB27: 26 | FC27: 26.4 | FD27: 26.8 | FE27: 26.9 | FF27: 27.1 | FG27: 27.3 | FH27: 27.6 | FI27: 28 | FJ27: 28.4 | FK27: 28.8
B28: Natural Gas/Electric | C28: 0 | D28: 0 | E28: 0 | F28: 0 | G28: 0 | H28: 0 | I28: 0 | J28: 0 | K28: 0 | L28: 0 | M28: 0 | N28: 0 | O28: 0 | P28: 0 | Q28: 0 | R28: 0 | S28: 0 | T28: 0 | U28: 0 | V28: 0 | W28: 0 | Z28: Natural Gas/Electric | AA28: 6.5 | AB28: 6.8 | AC28: 7.1 | AD28: 7.3 | AE28: 7.5 | AF28: 7.8 | AG28: 8 | AH28: 8.2 | AI28: 8.4 | AJ28: 8.6 | AK28: 8.8 | AL28: 9 | AM28: 9.2 | AN28: 9.4 | AO28: 9.6 | AP28: 9.8 | AQ28: 10.1 | AR28: 10.3 | AS28: 10.6 | AT28: 10.9 | AU28: 11.2 | AX28: Natural Gas/Electric | AY28: 16.4 | AZ28: 17 | BA28: 17.6 | BB28: 18.2 | BC28: 18.7 | BD28: 19.3 | BE28: 19.7 | BF28: 20.2 | BG28: 20.7 | BH28: 21.2 | BI28: 21.6 | BJ28: 22 | BK28: 22.5 | BL28: 23 | BM28: 23.1 | BN28: 23.3 | BO28: 23.6 | BP28: 24 | BQ28: 24.4 | BR28: 24.9 | BS28: 25.4 | BV28: Natural Gas/Electric | BW28: 0.3 | BX28: 0.3 | BY28: 0.3 | BZ28: 0.4 | CA28: 0.4 | CB28: 0.4 | CC28: 0.4 | CD28: 0.4 | CE28: 0.4 | CF28: 0.4 | CG28: 0.4 | CH28: 0.4 | CI28: 0.4 | CJ28: 0.4 | CK28: 0.5 | CL28: 0.5 | CM28: 0.5 | CN28: 0.5 | CO28: 0.5 | CP28: 0.5 | CQ28: 0.5 | CT28: Natural Gas/Electric | CU28: 1.4 | CV28: 1.4 | CW28: 1.5 | CX28: 1.5 | CY28: 1.5 | CZ28: 1.6 | DA28: 1.6 | DB28: 1.7 | DC28: 1.7 | DD28: 1.8 | DE28: 1.8 | DF28: 1.8 | DG28: 1.9 | DH28: 1.9 | DI28: 2 | DJ28: 2 | DK28: 2.1 | DL28: 2.1 | DM28: 2.1 | DN28: 2.2 | DO28: 2.2 | DR28: Natural Gas/Electric | DS28: 2.1 | DT28: 2.2 | DU28: 2.4 | DV28: 2.5 | DW28: 2.6 | DX28: 2.7 | DY28: 2.8 | DZ28: 2.9 | EA28: 3 | EB28: 3.1 | EC28: 3.2 | ED28: 3.3 | EE28: 3.4 | EF28: 3.5 | EG28: 3.6 | EH28: 3.7 | EI28: 3.8 | EJ28: 3.9 | EK28: 4 | EL28: 4 | EM28: 4.1 | EP28: Natural Gas/Electric | EQ28: 12.4 | ER28: 12.9 | ES28: 13.3 | ET28: 13.8 | EU28: 14.1 | EV28: 14.4 | EW28: 14.8 | EX28: 15.2 | EY28: 15.5 | EZ28: 15.8 | FA28: 16.2 | FB28: 16.5 | FC28: 16.9 | FD28: 17.2 | FE28: 17.4 | FF28: 17.5 | FG28: 17.8 | FH28: 18 | FI28: 18.4 | FJ28: 18.7 | FK28: 19
B29: Heating Oil/Electric | C29: 3.6 | D29: 3.7 | E29: 3.9 | F29: 4 | G29: 4.1 | H29: 4.3 | I29: 4.4 | J29: 4.5 | K29: 4.6 | L29: 4.7 | M29: 4.8 | N29: 4.9 | O29: 4.9 | P29: 5 | Q29: 5.1 | R29: 5.2 | S29: 5.2 | T29: 5.3 | U29: 5.5 | V29: 5.6 | W29: 5.7 | Z29: Heating Oil/Electric | AA29: 74.4 | AB29: 76.6 | AC29: 78.6 | AD29: 80.6 | AE29: 82.6 | AF29: 84.5 | AG29: 86.2 | AH29: 87.8 | AI29: 89.7 | AJ29: 91.6 | AK29: 93.2 | AL29: 94.6 | AM29: 96.2 | AN29: 97.8 | AO29: 99.5 | AP29: 101.3 | AQ29: 103.2 | AR29: 105.4 | AS29: 107.9 | AT29: 110.5 | AU29: 113.1 | AX29: Heating Oil/Electric | AY29: 10.3 | AZ29: 10.6 | BA29: 11 | BB29: 11.4 | BC29: 11.7 | BD29: 12 | BE29: 12.3 | BF29: 12.6 | BG29: 12.9 | BH29: 13.2 | BI29: 13.4 | BJ29: 13.7 | BK29: 14 | BL29: 14.2 | BM29: 14.3 | BN29: 14.5 | BO29: 14.6 | BP29: 14.9 | BQ29: 15.1 | BR29: 15.4 | BS29: 15.7 | BV29: Heating Oil/Electric | BW29: 1 | BX29: 1 | BY29: 1.1 | BZ29: 1.1 | CA29: 1.1 | CB29: 1.2 | CC29: 1.2 | CD29: 1.3 | CE29: 1.3 | CF29: 1.3 | CG29: 1.4 | CH29: 1.4 | CI29: 1.4 | CJ29: 1.5 | CK29: 1.5 | CL29: 1.5 | CM29: 1.5 | CN29: 1.6 | CO29: 1.6 | CP29: 1.6 | CQ29: 1.7 | CT29: Heating Oil/Electric | CU29: 1.1 | CV29: 1.1 | CW29: 1.2 | CX29: 1.2 | CY29: 1.2 | CZ29: 1.3 | DA29: 1.3 | DB29: 1.3 | DC29: 1.4 | DD29: 1.4 | DE29: 1.4 | DF29: 1.5 | DG29: 1.5 | DH29: 1.5 | DI29: 1.6 | DJ29: 1.6 | DK29: 1.6 | DL29: 1.6 | DM29: 1.7 | DN29: 1.7 | DO29: 1.7 | DR29: Heating Oil/Electric | DS29: 0.1 | DT29: 0.1 | DU29: 0.1 | DV29: 0.1 | DW29: 0.1 | DX29: 0.1 | DY29: 0.1 | DZ29: 0.1 | EA29: 0.1 | EB29: 0.1 | EC29: 0.1 | ED29: 0.1 | EE29: 0.1 | EF29: 0.1 | EG29: 0.1 | EH29: 0.1 | EI29: 0.1 | EJ29: 0.1 | EK29: 0.1 | EL29: 0.1 | EM29: 0.1 | EP29: Heating Oil/Electric | EQ29: 6 | ER29: 6.2 | ES29: 6.5 | ET29: 6.8 | EU29: 7 | EV29: 7.2 | EW29: 7.4 | EX29: 7.6 | EY29: 7.8 | EZ29: 8 | FA29: 8.2 | FB29: 8.4 | FC29: 8.7 | FD29: 8.9 | FE29: 9 | FF29: 9.1 | FG29: 9.2 | FH29: 9.4 | FI29: 9.6 | FJ29: 9.8 | FK29: 10
B31: Shares (%) | Z31: Shares (%) | AX31: Shares (%) | BV31: Shares (%) | CT31: Shares (%) | DR31: Shares (%) | EP31: Shares (%)
B32: Heating Oil – Normal Efficiency | C32: 15 | D32: 13 | E32: 11 | F32: 9.1 | G32: 7.5 | H32: 5.9 | I32: 4.5 | J32: 3.3 | K32: 2.2 | L32: 0.8 | M32: 0.1 | N32: 0 | O32: 0 | P32: 0 | Q32: 0 | R32: 0 | S32: 0 | T32: 0 | U32: 0 | V32: 0 | W32: 0 | Z32: Heating Oil – Normal Efficiency | AA32: 0 | AB32: 0 | AC32: 0 | AD32: 0 | AE32: 0 | AF32: 0 | AG32: 0 | AH32: 0 | AI32: 0 | AJ32: 0 | AK32: 0 | AL32: 0 | AM32: 0 | AN32: 0 | AO32: 0 | AP32: 0 | AQ32: 0 | AR32: 0 | AS32: 0 | AT32: 0 | AU32: 0 | AX32: Heating Oil – Normal Efficiency | AY32: 2.3 | AZ32: 1.6 | BA32: 0.8 | BB32: 0.3 | BC32: 0 | BD32: 0 | BE32: 0 | BF32: 0 | BG32: 0 | BH32: 0 | BI32: 0 | BJ32: 0 | BK32: 0 | BL32: 0 | BM32: 0 | BN32: 0 | BO32: 0 | BP32: 0 | BQ32: 0 | BR32: 0 | BS32: 0 | BV32: Heating Oil – Normal Efficiency | BW32: 0.5 | BX32: 0.3 | BY32: 0.1 | BZ32: 0 | CA32: 0 | CB32: 0 | CC32: 0 | CD32: 0 | CE32: 0 | CF32: 0 | CG32: 0 | CH32: 0 | CI32: 0 | CJ32: 0 | CK32: 0 | CL32: 0 | CM32: 0 | CN32: 0 | CO32: 0 | CP32: 0 | CQ32: 0 | CT32: Heating Oil – Normal Efficiency | CU32: 1.4 | CV32: 0.8 | CW32: 0.3 | CX32: 0 | CY32: 0 | CZ32: 0 | DA32: 0 | DB32: 0 | DC32: 0 | DD32: 0 | DE32: 0 | DF32: 0 | DG32: 0 | DH32: 0 | DI32: 0 | DJ32: 0 | DK32: 0 | DL32: 0 | DM32: 0 | DN32: 0 | DO32: 0 | DR32: Heating Oil – Normal Efficiency | DS32: 0.5 | DT32: 0.4 | DU32: 0.3 | DV32: 0.3 | DW32: 0.2 | DX32: 0.2 | DY32: 0.1 | DZ32: 0.1 | EA32: 0 | EB32: 0 | EC32: 0 | ED32: 0 | EE32: 0 | EF32: 0 | EG32: 0 | EH32: 0 | EI32: 0 | EJ32: 0 | EK32: 0 | EL32: 0 | EM32: 0 | EP32: Heating Oil – Normal Efficiency | EQ32: 2.4 | ER32: 1.8 | ES32: 1.2 | ET32: 0.6 | EU32: 0.5 | EV32: 0.5 | EW32: 0.4 | EX32: 0.4 | EY32: 0.4 | EZ32: 0.3 | FA32: 0.3 | FB32: 0.2 | FC32: 0.2 | FD32: 0.2 | FE32: 0.2 | FF32: 0.2 | FG32: 0.1 | FH32: 0.1 | FI32: 0.1 | FJ32: 0.1 | FK32: 0.1
